Workbook

Sheet Entrada
A1: Data | B1: Polígono | C1: Emulsão | D1: Furos | E1: Média Kg/Furo | F1: UMB | G1: Operador | H1: Acumulado Emulsão | I1: Acumulado Furos
A2: 45659 | B2: PP02-060125 | C2: 15304 | D2: 165 | E2: =IF(D2>0,(C2/D2),"*") -> 92.751515 | F2: 1072 | G2: DEIVYS | H2: =C2 -> 15304 | I2: =C2+D2 -> 15469 | J2: Ano 2025
A3: 45659 | B3: PP02-060125 | C3: 9577 | D3: 119 | E3: =IF(D3>0,(C3/D3),"*") -> 80.478992 | F3: 1123 | G3: GILMAR | H3: =H2+C3 -> 24881 | I3: =I2+D3 -> 15588
A4: 45664 | B4: PP040125 | C4: 9110 | D4: 72 | E4: =IF(D4>0,(C4/D4),"*") -> 126.52778 | F4: 1072 | G4: DEIVYS | H4: =H3+C4 -> 33991 | I4: =I3+D4 -> 15660
A5: 45665 | B5: PP030125 | C5: 11854 | D5: 89 | E5: =IF(D5>0,(C5/D5),"*") -> 133.19101 | F5: 1072 | G5: DEIVYS | H5: =H4+C5 -> 45845 | I5: =I4+D5 -> 15749
A6: 45665 | B6: PP030125 | C6: 16055 | D6: 130 | E6: =IF(D6>0,(C6/D6),"*") -> 123.5 | F6: 1123 | G6: GILMAR | H6: =H5+C6 -> 61900 | I6: =I5+D6 -> 15879
A7: 45666 | B7: PP030125 | C7: 2167 | D7: 19 | E7: =IF(D7>0,(C7/D7),"*") -> 114.05263 | F7: 1072 | G7: DEIVYS | H7: =H6+C7 -> 64067 | I7: =I6+D7 -> 15898
A8: 45666 | B8: PP040125 | C8: 7087 | D8: 58 | E8: =IF(D8>0,(C8/D8),"*") -> 122.18966 | F8: 1072 | G8: DEIVYS | H8: =H7+C8 -> 71154 | I8: =I7+D8 -> 15956
A9: 45666 | B9: PP040125 | C9: 5818 | D9: 44 | E9: =IF(D9>0,(C9/D9),"*") -> 132.22727 | F9: 1123 | G9: GILMAR | H9: =H8+C9 -> 76972 | I9: =I8+D9 -> 16000
A10: 45668 | B10: PP080125 | C10: 8869 | D10: 72 | E10: =IF(D10>0,(C10/D10),"*") -> 123.18056 | F10: 1123 | G10: GILMAR | H10: =H9+C10 -> 85841 | I10: =I9+D10 -> 16072
A11: 45670 | B11: PP080125 | C11: 12024 | D11: 107 | E11: =IF(D11>0,(C11/D11),"*") -> 112.37383 | F11: 1072 | G11: DEIVYS | H11: =H10+C11 -> 97865 | I11: =I10+D11 -> 16179
A12: 45670 | B12: PP080125 | C12: 10360 | D12: 90 | E12: =IF(D12>0,(C12/D12),"*") -> 115.11111 | F12: 1123 | G12: GILMAR | H12: =H11+C12 -> 108225 | I12: =I11+D12 -> 16269
A13: 45671 | B13: PP050125 | C13: 7079 | D13: 72 | E13: =IF(D13>0,(C13/D13),"*") -> 98.319444 | F13: 1123 | G13: GILMAR | H13: =H12+C13 -> 115304 | I13: =I12+D13 -> 16341
A14: 45672 | B14: PP050125 | C14: 8109 | D14: 66 | E14: =IF(D14>0,(C14/D14),"*") -> 122.86364 | F14: 1123 | G14: GILMAR | H14: =H13+C14 -> 123413 | I14: =I13+D14 -> 16407
... A350: 45938 | B350: PP1411025 | C350: 20097 | D350: 157 | E350: =IF(D350>0,(C350/D350),"*") -> 128.00637 | F350: 1123 | G350: GILMAR | H350: =H349+C350 -> 2978685 | I350: =I349+D350 -> 41086
A351: 45939 | B351: PP1411025 | C351: 19880 | D351: 164 | F351: 1123 | G351: GILMAR | H351: =H350+C351 -> 2998565 | I351: =I350+D351 -> 41250
A352: 45939 | B352: PP1411025 | C352: 20620 | D352: 149 | E352: =IF(D352>0,(C352/D352),"*") -> 138.38926 | F352: 1072 | G352: PAULO | H352: =H351+C352 -> 3019185 | I352: =I351+D352 -> 41399
A353: 45940 | B353: PP1411025 | C353: 1150 | D353: 9 | E353: =IF(D353>0,(C353/D353),"*") -> 127.77778 | F353: 1072 | G353: PAULO | H353: =H352+C353 -> 3020335 | I353: =I352+D353 -> 41408
A354: 45940 | B354: PP1391025 | C354: 4801 | D354: 45 | E354: =IF(D354>0,(C354/D354),"*") -> 106.68889 | F354: 1072 | G354: PAULO | H354: =H353+C354 -> 3025136 | I354: =I353+D354 -> 41453
A355: 45940 | B355: PP1391025 | C355: 4316 | D355: 34 | E355: =IF(D355>0,(C355/D355),"*") -> 126.94118 | F355: 1123 | G355: GILMAR | H355: =H354+C355 -> 3029452 | I355: =I354+D355 -> 41487
A356: 45943 | B356: PP1391025 | C356: 9281 | D356: 72 | E356: =IF(D356>0,(C356/D356),"*") -> 128.90278 | F356: 1123 | G356: GILMAR | H356: =H355+C356 -> 3038733 | I356: =I355+D356 -> 41559
A357: 45943 | B357: PP1391025 | C357: 15689 | D357: 122 | E357: =IF(D357>0,(C357/D357),"*") -> 128.59836 | F357: 1072 | G357: PAULO | H357: =H356+C357 -> 3054422 | I357: =I356+D357 -> 41681
A358: 45944 | B358: PP135B1025 | C358: 6084 | D358: 33 | E358: =IF(D358>0,(C358/D358),"*") -> 184.36364 | F358: 1072 | G358: PAULO | H358: =H357+C358 -> 3060506 | I358: =I357+D358 -> 41714
A359: 45945 | B359: PP114A1025 | C359: 5405 | D359: 44 | E359: =IF(D359>0,(C359/D359),"*") -> 122.84091 | F359: 1072 | G359: PAULO | H359: =H358+C359 -> 3065911 | I359: =I358+D359 -> 41758
A360: 45945 | B360: PP114A1025 | C360: 6361 | D360: 89 | E360: =IF(D360>0,(C360/D360),"*") -> 71.47191 | F360: 1123 | G360: GILMAR | H360: =H359+C360 -> 3072272 | I360: =I359+D360 -> 41847
A361: 45946 | B361: PP114A1025 | C361: 17306 | D361: 143 | E361: =IF(D361>0,(C361/D361),"*") -> 121.02098 | F361: 1123 | G361: GILMAR | H361: =H360+C361 -> 3089578 | I361: =I360+D361 -> 41990
A362: 45946 | B362: PP114A1025 | C362: 11720 | D362: 97 | E362: =IF(D362>0,(C362/D362),"*") -> 120.82474 | F362: 1072 | G362: PAULO | H362: =H361+C362 -> 3101298 | I362: =I361+D362 -> 42087
A363: 45947 | B363: PP1221025-REG | C363: 1078 | D363: 56 | E363: =IF(D363>0,(C363/D363),"*") -> 19.25 | F363: 1123 | G363: GILMAR | H363: =H362+C363 -> 3102376 | I363: =I362+D363 -> 42143
... A684: 46181 | B684: PP340626 | C684: 23232 | D684: 166 | E684: =IF(D684>0,(C684/D684),"*") -> 139.95181 | F684: 1072 | G684: THIAGO | H684: =H683+C684 -> 6488832 | I684: =I683+D684 -> 69120
E685: =IF(D685>0,(C685/D685),"*") -> * | H685: =H684+C685 -> 6488832 | I685: =I684+D685 -> 69120
E686: =IF(D686>0,(C686/D686),"*") -> * | H686: =H685+C686 -> 6488832 | I686: =I685+D686 -> 69120
E687: =IF(D687>0,(C687/D687),"*") -> * | H687: =H686+C687 -> 6488832 | I687: =I686+D687 -> 69120
E688: =IF(D688>0,(C688/D688),"*") -> * | H688: =H687+C688 -> 6488832 | I688: =I687+D688 -> 69120
E689: =IF(D689>0,(C689/D689),"*") -> * | H689: =H688+C689 -> 6488832 | I689: =I688+D689 -> 69120
E690: =IF(D690>0,(C690/D690),"*") -> * | H690: =H689+C690 -> 6488832 | I690: =I689+D690 -> 69120
E691: =IF(D691>0,(C691/D691),"*") -> * | H691: =H690+C691 -> 6488832 | I691: =I690+D691 -> 69120
E692: =IF(D692>0,(C692/D692),"*") -> * | H692: =H691+C692 -> 6488832 | I692: =I691+D692 -> 69120
E693: =IF(D693>0,(C693/D693),"*") -> * | H693: =H692+C693 -> 6488832 | I693: =I692+D693 -> 69120
E694: =IF(D694>0,(C694/D694),"*") -> * | H694: =H693+C694 -> 6488832 | I694: =I693+D694 -> 69120
E695: =IF(D695>0,(C695/D695),"*") -> * | H695: =H694+C695 -> 6488832 | I695: =I694+D695 -> 69120
...

Sheet Ritmo do Mês
A1: Ano | B1: Mês | C1: Dia_Represent | D1: Meta | E1: Ritmo | F1: Aplicado | G1: Diferença
A2: 2026 | B2: Janeiro | C2: 46023 | D2: 400000 | E2: =IFERROR( IF(F2=0,0, IF(AND(YEAR(C2)=YEAR(TODAY()),MONTH(C2)=MONTH(TODAY())), F2/MIN(DAY(TODAY()),DAY(EOMONTH(C2,0)))*DAY(EOMONTH(C2,0)), F2 ) ),0) -> 547771 | F2: =SUMIFS(Entrada!C:C,Entrada!A:A,">="&DATE(YEAR(C2),MONTH(C2),1),Entrada!A:A,"<="&EOMONTH(C2,0)) -> 547771 | G2: =D2-F2 -> -147771
A3: 2026 | B3: Fevereiro | C3: 46054 | D3: 400000 | E3: =IFERROR( IF(F3=0,0, IF(AND(YEAR(C3)=YEAR(TODAY()),MONTH(C3)=MONTH(TODAY())), F3/MIN(DAY(TODAY()),DAY(EOMONTH(C3,0)))*DAY(EOMONTH(C3,0)), F3 ) ),0) -> 381832 | F3: =SUMIFS(Entrada!C:C,Entrada!A:A,">="&DATE(YEAR(C3),MONTH(C3),1),Entrada!A:A,"<="&EOMONTH(C3,0)) -> 381832 | G3: =D3-F3 -> 18168
A4: 2026 | B4: Março | C4: 46082 | D4: 400000 | E4: =IFERROR( IF(F4=0,0, IF(AND(YEAR(C4)=YEAR(TODAY()),MONTH(C4)=MONTH(TODAY())), F4/MIN(DAY(TODAY()),DAY(EOMONTH(C4,0)))*DAY(EOMONTH(C4,0)), F4 ) ),0) -> 577816 | F4: =SUMIFS(Entrada!C:C,Entrada!A:A,">="&DATE(YEAR(C4),MONTH(C4),1),Entrada!A:A,"<="&EOMONTH(C4,0)) -> 577816 | G4: =D4-F4 -> -177816
A5: 2026 | B5: Abril | C5: 46113 | D5: 400000 | E5: =IFERROR( IF(F5=0,0, IF(AND(YEAR(C5)=YEAR(TODAY()),MONTH(C5)=MONTH(TODAY())), F5/MIN(DAY(TODAY()),DAY(EOMONTH(C5,0)))*DAY(EOMONTH(C5,0)), F5 ) ),0) -> 274096 | F5: =SUMIFS(Entrada!C:C,Entrada!A:A,">="&DATE(YEAR(C5),MONTH(C5),1),Entrada!A:A,"<="&EOMONTH(C5,0)) -> 274096 | G5: =D5-F5 -> 125904
A6: 2026 | B6: Maio | C6: 46143 | D6: 400000 | E6: =IFERROR( IF(F6=0,0, IF(AND(YEAR(C6)=YEAR(TODAY()),MONTH(C6)=MONTH(TODAY())), F6/MIN(DAY(TODAY()),DAY(EOMONTH(C6,0)))*DAY(EOMONTH(C6,0)), F6 ) ),0) -> 432211 | F6: =SUMIFS(Entrada!C:C,Entrada!A:A,">="&DATE(YEAR(C6),MONTH(C6),1),Entrada!A:A,"<="&EOMONTH(C6,0)) -> 432211 | G6: =D6-F6 -> -32211
A7: 2026 | B7: Junho | C7: 46174 | D7: 400000 | E7: =IFERROR( IF(F7=0,0, IF(AND(YEAR(C7)=YEAR(TODAY()),MONTH(C7)=MONTH(TODAY())), F7/MIN(DAY(TODAY()),DAY(EOMONTH(C7,0)))*DAY(EOMONTH(C7,0)), F7 ) ),0) -> 587178.75 | F7: =SUMIFS(Entrada!C:C,Entrada!A:A,">="&DATE(YEAR(C7),MONTH(C7),1),Entrada!A:A,"<="&EOMONTH(C7,0)) -> 156581 | G7: =D7-F7 -> 243419
A8: 2026 | B8: Julho | C8: 46204 | D8: 400000 | E8: =IFERROR( IF(F8=0,0, IF(AND(YEAR(C8)=YEAR(TODAY()),MONTH(C8)=MONTH(TODAY())), F8/MIN(DAY(TODAY()),DAY(EOMONTH(C8,0)))*DAY(EOMONTH(C8,0)), F8 ) ),0) -> 0 | F8: =SUMIFS(Entrada!C:C,Entrada!A:A,">="&DATE(YEAR(C8),MONTH(C8),1),Entrada!A:A,"<="&EOMONTH(C8,0)) -> 0 | G8: =D8-F8 -> 400000
A9: 2026 | B9: Agosto | C9: 46235 | D9: 400000 | E9: =IFERROR( IF(F9=0,0, IF(AND(YEAR(C9)=YEAR(TODAY()),MONTH(C9)=MONTH(TODAY())), F9/MIN(DAY(TODAY()),DAY(EOMONTH(C9,0)))*DAY(EOMONTH(C9,0)), F9 ) ),0) -> 0 | F9: =SUMIFS(Entrada!C:C,Entrada!A:A,">="&DATE(YEAR(C9),MONTH(C9),1),Entrada!A:A,"<="&EOMONTH(C9,0)) -> 0 | G9: =D9-F9 -> 400000
A10: 2026 | B10: Setembro | C10: 46266 | D10: 400000 | E10: =IFERROR( IF(F10=0,0, IF(AND(YEAR(C10)=YEAR(TODAY()),MONTH(C10)=MONTH(TODAY())), F10/MIN(DAY(TODAY()),DAY(EOMONTH(C10,0)))*DAY(EOMONTH(C10,0)), F10 ) ),0) -> 0 | F10: =SUMIFS(Entrada!C:C,Entrada!A:A,">="&DATE(YEAR(C10),MONTH(C10),1),Entrada!A:A,"<="&EOMONTH(C10,0)) -> 0 | G10: =D10-F10 -> 400000
A11: 2026 | B11: Outubro | C11: 46296 | D11: 400000 | E11: =IFERROR( IF(F11=0,0, IF(AND(YEAR(C11)=YEAR(TODAY()),MONTH(C11)=MONTH(TODAY())), F11/MIN(DAY(TODAY()),DAY(EOMONTH(C11,0)))*DAY(EOMONTH(C11,0)), F11 ) ),0) -> 0 | F11: =SUMIFS(Entrada!C:C,Entrada!A:A,">="&DATE(YEAR(C11),MONTH(C11),1),Entrada!A:A,"<="&EOMONTH(C11,0)) -> 0 | G11: =D11-F11 -> 400000
A12: 2026 | B12: Novembro | C12: 46327 | D12: 400000 | E12: =IFERROR( IF(F12=0,0, IF(AND(YEAR(C12)=YEAR(TODAY()),MONTH(C12)=MONTH(TODAY())), F12/MIN(DAY(TODAY()),DAY(EOMONTH(C12,0)))*DAY(EOMONTH(C12,0)), F12 ) ),0) -> 0 | F12: =SUMIFS(Entrada!C:C,Entrada!A:A,">="&DATE(YEAR(C12),MONTH(C12),1),Entrada!A:A,"<="&EOMONTH(C12,0)) -> 0 | G12: =D12-F12 -> 400000
A13: 2026 | B13: Dezembro | C13: 46357 | D13: 400000 | E13: =IFERROR( IF(F13=0,0, IF(AND(YEAR(C13)=YEAR(TODAY()),MONTH(C13)=MONTH(TODAY())), F13/MIN(DAY(TODAY()),DAY(EOMONTH(C13,0)))*DAY(EOMONTH(C13,0)), F13 ) ),0) -> 0 | F13: =SUMIFS(Entrada!C:C,Entrada!A:A,">="&DATE(YEAR(C13),MONTH(C13),1),Entrada!A:A,"<="&EOMONTH(C13,0)) -> 0 | G13: =D13-F13 -> 400000
... A37: 2024 | B37: Dezembro | C37: 45627 | D37: 400000 | E37: =IFERROR( IF(F37=0,0, IF(AND(YEAR(C37)=YEAR(TODAY()),MONTH(C37)=MONTH(TODAY())), F37/MIN(DAY(TODAY()),DAY(EOMONTH(C37,0)))*DAY(EOMONTH(C37,0)), F37 ) ),0) -> 0 | F37: =SUMIFS(Entrada!C:C,Entrada!A:A,">="&DATE(YEAR(C37),MONTH(C37),1),Entrada!A:A,"<="&EOMONTH(C37,0)) -> 0 | G37: =D37-F37 -> 400000
